<?xml version="1.0" ?>
<robot xmlns:xacro="http://www.ros.org/wiki/xacro" name="firefighter">
    <xacro:include filename="$(find mycobot_description)/urdf/mycobot_320_pi_2022/camera/depthcam.xacro"/>
    <xacro:include filename="$(find mycobot_description)/urdf/mycobot_320_pi_2022/wall.xacro"/>   
    
    <link name="world"/>
    <joint name="world_to_base" type="fixed">
        <parent link="world"/>
        <child link="base"/>
        <origin xyz="0 0 0.07" rpy="0 0 0"/>
    </joint>
    
    
    <link name="base">
        <visual>
            <geometry>
                <mesh filename="package://mycobot_description/urdf/mycobot_320_pi_2022/ade/base.dae" />
            </geometry>
            <origin xyz="0.0 0.0 0.0 " rpy=" 0 0 1.5708" />
        </visual>
        <collision>
            <origin xyz="0.0 0.0 0.0 " rpy=" 0 0 1.5708" />
            <geometry>
                <cylinder length="0.102" radius="0.0725" />
            </geometry>
        </collision>
        <inertial>
            <mass value="50" />
            <origin xyz="0 0 0" rpy="0 0 0" />
            <inertia ixx="0.001" iyy="0.001" izz="0.001" ixy="0.0" ixz="0.0" iyz="0.0" />
        </inertial>
    </link>
    
    
    <link name="link1">
        <visual>
            <geometry>
                <mesh filename="package://mycobot_description/urdf/mycobot_320_pi_2022/ade/link1.dae" />
            </geometry>
            <origin xyz="0.0 0.0 -0.078 " rpy=" 0 0 1.5708" />
        </visual>
        <collision>
            <origin xyz="0.0 0.0 -0.078 " rpy=" 0 0 1.5708" />
            <geometry>
                <cylinder length="0.106" radius="0.043" />
            </geometry>
        </collision>
        <inertial>
            <mass value="0.5" />
            <origin xyz="0 0 0" rpy="0 0 0" />
            <inertia ixx="0.001" iyy="0.001" izz="0.001" ixy="0.0" ixz="0.0" iyz="0.0" />
        </inertial>
    </link>
    
    
    <link name="link2">
        <visual>
            <geometry>
                <mesh filename="package://mycobot_description/urdf/mycobot_320_pi_2022/ade/link2.dae" />
            </geometry>
            <origin xyz="0.0 0.0 -0.04 " rpy=" 0 1.5708 0" />
        </visual>
        <collision>
            <origin xyz="0.0 0.0 -0.04 " rpy=" 0 1.5708 0" />
            <geometry>
                <cylinder length="0.18" radius="0.036" />
            </geometry>
        </collision>
        <inertial>
            <mass value="0.5" />
            <origin xyz="0 0 0" rpy="0 0 0" />
            <inertia ixx="0.001" iyy="0.001" izz="0.001" ixy="0.0" ixz="0.0" iyz="0.0" />
        </inertial>
    </link>
    
    
    <link name="link3">
        <visual>
            <geometry>
                <mesh filename="package://mycobot_description/urdf/mycobot_320_pi_2022/ade/link3.dae" />
            </geometry>
            <origin xyz="0.0 0.0 0.039 " rpy=" 1.5708 1.5708 1.5708" />
        </visual>
        <collision>
            <origin xyz="0.0 0.0 0.039 " rpy=" 1.5708 1.5708 1.5708" />
            <geometry>
                <cylinder length="0.14" radius="0.0305" />
            </geometry>
        </collision>
        <inertial>
            <mass value="0.5" />
            <origin xyz="0 0 0" rpy="0 0 0" />
            <inertia ixx="0.001" iyy="0.001" izz="0.001" ixy="0.0" ixz="0.0" iyz="0.0" />
        </inertial>
    </link>
    
    
    <link name="link4">
        <visual>
            <geometry>
                <mesh filename="package://mycobot_description/urdf/mycobot_320_pi_2022/ade/link4.dae" />
            </geometry>
            <origin xyz="0.0 -0.0024 -0.05" rpy=" 1.5708 1.5708 0" />
        </visual>
        <collision>
            <origin xyz="0.0 -0.0024 -0.05" rpy=" 1.5708 1.5708 0" />
            <geometry>
                <cylinder length="0.083" radius="0.029" />
            </geometry>
        </collision>
        <inertial>
            <mass value="0.5" />
            <origin xyz="0 0 0" rpy="0 0 0" />
            <inertia ixx="0.001" iyy="0.001" izz="0.001" ixy="0.0" ixz="0.0" iyz="0.0" />
        </inertial>
    </link>
    
    
    <link name="link5">
        <visual>
            <geometry>
                <mesh filename="package://mycobot_description/urdf/mycobot_320_pi_2022/ade/link5.dae" />
            </geometry>
            <origin xyz="0.0 0.0 -0.05 " rpy=" 0  0 -1.5708" />
        </visual>
        <collision>
            <origin xyz="0.0 0.0 -0.05 " rpy=" 0  0 -1.5708" />
            <geometry>
                <cylinder length="0.0849" radius="0.029" />
            </geometry>
        </collision>
        <inertial>
            <mass value="0.5" />
            <origin xyz="0 0 0" rpy="0 0 0" />
            <inertia ixx="0.001" iyy="0.001" izz="0.001" ixy="0.0" ixz="0.0" iyz="0.0" />
        </inertial>
    </link>
    
    
    <link name="link6">
        <visual>
            <geometry>
                <mesh filename="package://mycobot_description/urdf/mycobot_320_pi_2022/ade/link6.dae" />
            </geometry>
            <material name="grey">
                <color rgba="0.5 0.5 0.5 1" />
            </material>
            <origin xyz="0.0 0.0 -0.022 " rpy=" 1.5708 1.5708 0" />
        </visual>
        <collision>
            <origin xyz="0.0 0.0 -0.022 " rpy=" 1.5708 1.5708 0" />
            <geometry>
                <cylinder length="0.0225" radius="0.026" />
            </geometry>
        </collision>
        <inertial>
            <mass value="0.5" />
            <origin xyz="0 0 0" rpy="0 0 0" />
            <inertia ixx="0.001" iyy="0.001" izz="0.001" ixy="0.0" ixz="0.0" iyz="0.0" />
        </inertial>
    </link>
    
    
    <xacro:realsense_d435 sensor_name="d435" parent_link="link6" rate="10">
      <origin rpy="0 -1.5708 1.5708 " xyz="0 -0.05 -0.015"/>
    </xacro:realsense_d435>
    
    
    <joint name="joint2_to_joint1" type="revolute">
        <axis xyz="0 0 1" />
        <limit effort="5000.0" lower="-2.96" upper="2.96" velocity="2.0" />
        <parent link="base" />
        <child link="link1" />
        <origin xyz="0 0 0.173" rpy="0 0 0" />
    </joint>
    
    
    <joint name="joint3_to_joint2" type="revolute">
        <axis xyz="0 0 1" />
        <limit effort="5000.0" lower="-2.79" upper="2.79" velocity="2.0" />
        <parent link="link1" />
        <child link="link2" />
        <origin xyz="0 -0.086  0" rpy="0 -1.57080  1.57080" />
    </joint>
    
    
    <joint name="joint4_to_joint3" type="revolute">
        <axis xyz=" 0 0 1" />
        <limit effort="5000.0" lower="-2.79" upper="2.79" velocity="2.0" />
        <parent link="link2" />
        <child link="link3" />
        <origin xyz="0.13635 0 -0.086   " rpy="0 0 0" />
    </joint>
    
    
    <joint name="joint5_to_joint4" type="revolute">
        <axis xyz=" 0 0 1" />
        <limit effort="5000.0" lower="-2.79" upper="2.79" velocity="2.0" />
        <parent link="link3" />
        <child link="link4" />
        <origin xyz="0.1195 0  0.082" rpy="0 0 1.57080" />
    </joint>
    
    
    <joint name="joint6_to_joint5" type="revolute">
        <axis xyz="0 0 1" />
        <limit effort="5000.0" lower="-2.96" upper="2.96" velocity="2.0" />
        <parent link="link4" />
        <child link="link5" />
        <origin xyz="0 -0.09415 0" rpy="1.57080 0 0" />
    </joint>
    
    
    <joint name="joint6output_to_joint6" type="revolute">
        <axis xyz="0 0 1" />
        <limit effort="5000.0" lower="-3.05" upper="3.05" velocity="2.0" />
        <parent link="link5" />
        <child link="link6" />
        <origin xyz="0 0.055 0" rpy="-1.57080 0 0 " />
    </joint>
    
    
    <transmission name="trans_joint2_to_joint1">
        <type>transmission_interface/SimpleTransmission</type>
        <joint name="joint2_to_joint1">
            <hardwareInterface>hardware_interface/EffortJointInterface</hardwareInterface>
        </joint>
        <actuator name="joint2_to_joint1_motor">
            <hardwareInterface>hardware_interface/EffortJointInterface</hardwareInterface>
            <mechanicalReduction>1</mechanicalReduction>
        </actuator>
    </transmission>
    
    
    <transmission name="trans_joint3_to_joint2">
        <type>transmission_interface/SimpleTransmission</type>
        <joint name="joint3_to_joint2">
            <hardwareInterface>hardware_interface/EffortJointInterface</hardwareInterface>
        </joint>
        <actuator name="joint3_to_joint2_motor">
            <hardwareInterface>hardware_interface/EffortJointInterface</hardwareInterface>
            <mechanicalReduction>1</mechanicalReduction>
        </actuator>
    </transmission>
    
    
    <transmission name="trans_joint4_to_joint3">
        <type>transmission_interface/SimpleTransmission</type>
        <joint name="joint4_to_joint3">
            <hardwareInterface>hardware_interface/EffortJointInterface</hardwareInterface>
        </joint>
        <actuator name="joint4_to_joint3_motor">
            <hardwareInterface>hardware_interface/EffortJointInterface</hardwareInterface>
            <mechanicalReduction>1</mechanicalReduction>
        </actuator>
    </transmission>
    
    
    <transmission name="trans_joint5_to_joint4">
        <type>transmission_interface/SimpleTransmission</type>
        <joint name="joint5_to_joint4">
            <hardwareInterface>hardware_interface/EffortJointInterface</hardwareInterface>
        </joint>
        <actuator name="joint5_to_joint4_motor">
            <hardwareInterface>hardware_interface/EffortJointInterface</hardwareInterface>
            <mechanicalReduction>1</mechanicalReduction>
        </actuator>
    </transmission>
    
    
    <transmission name="trans_joint6_to_joint5">
        <type>transmission_interface/SimpleTransmission</type>
        <joint name="joint6_to_joint5">
            <hardwareInterface>hardware_interface/EffortJointInterface</hardwareInterface>
        </joint>
        <actuator name="joint6_to_joint5_motor">
            <hardwareInterface>hardware_interface/EffortJointInterface</hardwareInterface>
            <mechanicalReduction>1</mechanicalReduction>
        </actuator>
    </transmission>
    
    
    <transmission name="trans_joint6output_to_joint6">
        <type>transmission_interface/SimpleTransmission</type>
        <joint name="joint6output_to_joint6">
            <hardwareInterface>hardware_interface/EffortJointInterface</hardwareInterface>
        </joint>
        <actuator name="joint6output_to_joint6_motor">
            <hardwareInterface>hardware_interface/EffortJointInterface</hardwareInterface>
            <mechanicalReduction>1</mechanicalReduction>
        </actuator>
    </transmission>
    
    
    
    <gazebo>
        <plugin name="gazebo_ros_control" filename="libgazebo_ros_control.so">
            <robotNamespace>/</robotNamespace>
        </plugin>
    </gazebo>



</robot>

